./start_gunicorn.sh: line 16: exec: gunicorn: not found
./start_gunicorn.sh: line 16: exec: gunicorn: not found
./start_gunicorn.sh: line 16: exec: gunicorn: not found
./start_gunicorn.sh: line 16: exec: gunicorn: not found
./start_gunicorn.sh: line 16: exec: gunicorn: not found
./start_gunicorn.sh: line 16: exec: gunicorn: not found
[2019-05-30 20:23:45 +0000] [1414] [DEBUG] Current configuration:
  proxy_protocol: False
  worker_connections: 1000
  statsd_host: None
  max_requests_jitter: 0
  post_fork: <function post_fork at 0x7faa8ae77cf8>
  errorlog: /home/ubuntu/assisteca-back/gunicorn.log
  enable_stdio_inheritance: False
  worker_class: sync
  ssl_version: 2
  suppress_ragged_eofs: True
  syslog: False
  syslog_facility: user
  when_ready: <function when_ready at 0x7faa8ae77a28>
  pre_fork: <function pre_fork at 0x7faa8ae77b90>
  cert_reqs: 0
  preload_app: False
  keepalive: 2
  accesslog: None
  group: 1000
  graceful_timeout: 30
  do_handshake_on_connect: False
  spew: False
  workers: 3
  proc_name: None
  sendfile: None
  pidfile: None
  umask: 0
  on_reload: <function on_reload at 0x7faa8ae778c0>
  pre_exec: <function pre_exec at 0x7faa8ae7e320>
  worker_tmp_dir: None
  limit_request_fields: 100
  pythonpath: None
  on_exit: <function on_exit at 0x7faa8ae7eb18>
  config: None
  logconfig: None
  check_config: False
  statsd_prefix: 
  secure_scheme_headers: {'X-FORWARDED-PROTOCOL': 'ssl', 'X-FORWARDED-PROTO': 'https', 'X-FORWARDED-SSL': 'on'}
  reload_engine: auto
  proxy_allow_ips: ['127.0.0.1']
  pre_request: <function pre_request at 0x7faa8ae7e488>
  post_request: <function post_request at 0x7faa8ae7e578>
  forwarded_allow_ips: ['127.0.0.1']
  worker_int: <function worker_int at 0x7faa8ae7e050>
  raw_paste_global_conf: []
  threads: 1
  max_requests: 0
  chdir: /home/ubuntu/assisteca-back
  daemon: False
  user: 1000
  limit_request_line: 4094
  access_log_format: %(h)s %(l)s %(u)s %(t)s "%(r)s" %(s)s %(b)s "%(f)s" "%(a)s"
  certfile: None
  on_starting: <function on_starting at 0x7faa8ae77758>
  post_worker_init: <function post_worker_init at 0x7faa8ae77e60>
  child_exit: <function child_exit at 0x7faa8ae7e6e0>
  worker_exit: <function worker_exit at 0x7faa8ae7e848>
  paste: None
  default_proc_name: assisteca-back.wsgi:application
  syslog_addr: udp://localhost:514
  syslog_prefix: None
  ciphers: TLSv1
  worker_abort: <function worker_abort at 0x7faa8ae7e1b8>
  loglevel: debug
  bind: ['127.0.0.1:8000']
  raw_env: []
  initgroups: False
  capture_output: False
  reload: False
  limit_request_field_size: 8190
  nworkers_changed: <function nworkers_changed at 0x7faa8ae7e9b0>
  timeout: 30
  keyfile: None
  ca_certs: None
  tmp_upload_dir: None
  backlog: 2048
  logger_class: gunicorn.glogging.Logger
[2019-05-30 20:23:45 +0000] [1414] [INFO] Starting gunicorn 19.7.1
[2019-05-30 20:23:45 +0000] [1414] [DEBUG] Arbiter booted
[2019-05-30 20:23:45 +0000] [1414] [INFO] Listening at: http://127.0.0.1:8000 (1414)
[2019-05-30 20:23:45 +0000] [1414] [INFO] Using worker: sync
[2019-05-30 20:23:45 +0000] [1418] [INFO] Booting worker with pid: 1418
[2019-05-30 20:23:45 +0000] [1418] [ERROR] Exception in worker process
Traceback (most recent call last):
  File "/usr/lib/python2.7/dist-packages/gunicorn/arbiter.py", line 578, in spawn_worker
    worker.init_process()
  File "/usr/lib/python2.7/dist-packages/gunicorn/workers/base.py", line 126, in init_process
    self.load_wsgi()
  File "/usr/lib/python2.7/dist-packages/gunicorn/workers/base.py", line 135, in load_wsgi
    self.wsgi = self.app.wsgi()
  File "/usr/lib/python2.7/dist-packages/gunicorn/app/base.py", line 67, in wsgi
    self.callable = self.load()
  File "/usr/lib/python2.7/dist-packages/gunicorn/app/wsgiapp.py", line 65, in load
    return self.load_wsgiapp()
  File "/usr/lib/python2.7/dist-packages/gunicorn/app/wsgiapp.py", line 52, in load_wsgiapp
    return util.import_app(self.app_uri)
  File "/usr/lib/python2.7/dist-packages/gunicorn/util.py", line 377, in import_app
    __import__(module)
ImportError: No module named assisteca-back.wsgi
[2019-05-30 20:23:45 +0000] [1418] [INFO] Worker exiting (pid: 1418)
[2019-05-30 20:23:45 +0000] [1414] [INFO] Shutting down: Master
[2019-05-30 20:23:45 +0000] [1414] [INFO] Reason: Worker failed to boot.
[2019-05-30 20:27:04 +0000] [1463] [DEBUG] Current configuration:
  proxy_protocol: False
  worker_connections: 1000
  statsd_host: None
  max_requests_jitter: 0
  post_fork: <function post_fork at 0x7fdc9b3c2cf8>
  errorlog: /home/ubuntu/assisteca-back/gunicorn.log
  enable_stdio_inheritance: False
  worker_class: sync
  ssl_version: 2
  suppress_ragged_eofs: True
  syslog: False
  syslog_facility: user
  when_ready: <function when_ready at 0x7fdc9b3c2a28>
  pre_fork: <function pre_fork at 0x7fdc9b3c2b90>
  cert_reqs: 0
  preload_app: False
  keepalive: 2
  accesslog: None
  group: 1000
  graceful_timeout: 30
  do_handshake_on_connect: False
  spew: False
  workers: 3
  proc_name: None
  sendfile: None
  pidfile: None
  umask: 0
  on_reload: <function on_reload at 0x7fdc9b3c28c0>
  pre_exec: <function pre_exec at 0x7fdc9b3c9320>
  worker_tmp_dir: None
  limit_request_fields: 100
  pythonpath: None
  on_exit: <function on_exit at 0x7fdc9b3c9b18>
  config: None
  logconfig: None
  check_config: False
  statsd_prefix: 
  secure_scheme_headers: {'X-FORWARDED-PROTOCOL': 'ssl', 'X-FORWARDED-PROTO': 'https', 'X-FORWARDED-SSL': 'on'}
  reload_engine: auto
  proxy_allow_ips: ['127.0.0.1']
  pre_request: <function pre_request at 0x7fdc9b3c9488>
  post_request: <function post_request at 0x7fdc9b3c9578>
  forwarded_allow_ips: ['127.0.0.1']
  worker_int: <function worker_int at 0x7fdc9b3c9050>
  raw_paste_global_conf: []
  threads: 1
  max_requests: 0
  chdir: /home/ubuntu/assisteca-back
  daemon: False
  user: 1000
  limit_request_line: 4094
  access_log_format: %(h)s %(l)s %(u)s %(t)s "%(r)s" %(s)s %(b)s "%(f)s" "%(a)s"
  certfile: None
  on_starting: <function on_starting at 0x7fdc9b3c2758>
  post_worker_init: <function post_worker_init at 0x7fdc9b3c2e60>
  child_exit: <function child_exit at 0x7fdc9b3c96e0>
  worker_exit: <function worker_exit at 0x7fdc9b3c9848>
  paste: None
  default_proc_name: assisteca-back.wsgi:application
  syslog_addr: udp://localhost:514
  syslog_prefix: None
  ciphers: TLSv1
  worker_abort: <function worker_abort at 0x7fdc9b3c91b8>
  loglevel: debug
  bind: ['127.0.0.1:8000']
  raw_env: []
  initgroups: False
  capture_output: False
  reload: False
  limit_request_field_size: 8190
  nworkers_changed: <function nworkers_changed at 0x7fdc9b3c99b0>
  timeout: 30
  keyfile: None
  ca_certs: None
  tmp_upload_dir: None
  backlog: 2048
  logger_class: gunicorn.glogging.Logger
[2019-05-30 20:27:04 +0000] [1463] [INFO] Starting gunicorn 19.7.1
[2019-05-30 20:27:04 +0000] [1463] [DEBUG] Arbiter booted
[2019-05-30 20:27:04 +0000] [1463] [INFO] Listening at: http://127.0.0.1:8000 (1463)
[2019-05-30 20:27:04 +0000] [1463] [INFO] Using worker: sync
[2019-05-30 20:27:04 +0000] [1467] [INFO] Booting worker with pid: 1467
[2019-05-30 20:27:04 +0000] [1467] [ERROR] Exception in worker process
Traceback (most recent call last):
  File "/usr/lib/python2.7/dist-packages/gunicorn/arbiter.py", line 578, in spawn_worker
    worker.init_process()
  File "/usr/lib/python2.7/dist-packages/gunicorn/workers/base.py", line 126, in init_process
    self.load_wsgi()
  File "/usr/lib/python2.7/dist-packages/gunicorn/workers/base.py", line 135, in load_wsgi
    self.wsgi = self.app.wsgi()
  File "/usr/lib/python2.7/dist-packages/gunicorn/app/base.py", line 67, in wsgi
    self.callable = self.load()
  File "/usr/lib/python2.7/dist-packages/gunicorn/app/wsgiapp.py", line 65, in load
    return self.load_wsgiapp()
  File "/usr/lib/python2.7/dist-packages/gunicorn/app/wsgiapp.py", line 52, in load_wsgiapp
    return util.import_app(self.app_uri)
  File "/usr/lib/python2.7/dist-packages/gunicorn/util.py", line 377, in import_app
    __import__(module)
ImportError: No module named assisteca-back.wsgi
[2019-05-30 20:27:04 +0000] [1467] [INFO] Worker exiting (pid: 1467)
[2019-05-30 20:27:04 +0000] [1463] [INFO] Shutting down: Master
[2019-05-30 20:27:04 +0000] [1463] [INFO] Reason: Worker failed to boot.
